Workbook

Sheet Guide
A1: How this workbook works
A3: 1. Player Data: 100 SIMULATED players with all 89 RG data points (columns coloured by category). Replace with real, approved, anonymised data in the same layout to use it for real.
A4: 2. Model Settings: each model's indicators, rules, thresholds (blue, editable) and weights (blue, editable), with the research basis for each.
A5: 3. Model Results: 12 models per player, all formulas. Scores are 0–100 = % of weighted warning signs triggered.
A6: M1 Overall harm risk · M2 Early warning (new accounts) · M3 Chasing losses · M4 Financial vulnerability · M5 Binge/episode · M6 Self-exclusion prediction
A7: M7 Player segment (Catania-style types) · M8 Harm language alert · M9 Marketing filter · M10 Behaviour change · M11 Spain DGOJ-style check · M12 Intervention effectiveness
A8: 4. Overall risk band: High if hard rules fire (harm language, third-party contact, national self-exclusion match) or M1 ≥ High; Medium if M1 ≥ Medium or M3/M5/M10 ≥ flag %.
A9: 5. Accuracy Test: compares flags with the simulated outcome (TP, FP, FN, TN, accuracy, sensitivity, specificity, precision). Switch High vs High+Medium to see the trade-off.
A11: Important:
A12: • These are rule-based (scorecard) versions of the models, which Excel can calculate. Machine-learning versions (logistic regression, LightGBM, etc.) are trained in Python on the same columns.
A13: • M11 is a DGOJ-STYLE check built from the publicly described indicator types; it is NOT the official DGOJ algorithm, whose 62 variables are issued to operators.
A14: • PGSI score (RG-079) and the simulated outcome are NOT used as model inputs, to avoid leakage.
A15: • Results on simulated data do not show real-world accuracy. Expect well below 100% on real data (published AUCs ≈ 0.6–0.84).

Sheet Player Data
A1: Synthetic player data – 100 players × 89 RG data points
A2: SIMULATED data for testing models only – not real players. Header colour = category (see RG Data Points workbook). Last column is a simulated outcome used only to test accuracy.
A4: RG ID | B4: RG-001 | C4: RG-002 | D4: RG-003 | E4: RG-004 | F4: RG-005 | G4: RG-006 | H4: RG-007 | I4: RG-008 | J4: RG-009 | K4: RG-010 | L4: RG-011 | M4: RG-012 | N4: RG-013 | O4: RG-014 | P4: RG-015 | Q4: RG-016 | R4: RG-017 | S4: RG-018 | T4: RG-019 | U4: RG-020 | V4: RG-021 | W4: RG-022 | X4: RG-023 | Y4: RG-024 | Z4: RG-025 | AA4: RG-026 | AB4: RG-027 | AC4: RG-028 | AD4: RG-029 | AE4: RG-030 | AF4: RG-031 | AG4: RG-032 | AH4: RG-033 | AI4: RG-034 | AJ4: RG-035 | AK4: RG-036 | AL4: RG-037 | AM4: RG-038 | AN4: RG-039 | AO4: RG-040 | AP4: RG-041 | AQ4: RG-042 | AR4: RG-043 | AS4: RG-044 | AT4: RG-045 | AU4: RG-046 | AV4: RG-047 | AW4: RG-048 | AX4: RG-049 | AY4: RG-050 | AZ4: RG-051 | BA4: RG-052 | BB4: RG-053 | BC4: RG-054 | BD4: RG-055 | BE4: RG-056 | BF4: RG-057 | BG4: RG-058 | BH4: RG-059 | BI4: RG-060 | BJ4: RG-061 | BK4: RG-062 | BL4: RG-063 | BM4: RG-064 | BN4: RG-065 | BO4: RG-066 | BP4: RG-067 | BQ4: RG-068 | BR4: RG-069 | BS4: RG-070 | BT4: RG-071 | BU4: RG-072 | BV4: RG-073 | BW4: RG-074 | BX4: RG-075 | BY4: RG-076 | BZ4: RG-077 | CA4: RG-078 | CB4: RG-079 | CC4: RG-080 | CD4: RG-081 | CE4: RG-082 | CF4: RG-083 | CG4: RG-084 | CH4: RG-085 | CI4: RG-086 | CJ4: RG-087 | CK4: RG-088 | CL4: RG-089
A5: Player ID | B5: Age (years) | C5: Gender | D5: Country / jurisdiction | E5: Account age (days) | F5: Income / occupation band | G5: VIP / high-value status | H5: Active days (days, last 30d) | I5: Number of sessions (count, 30d) | J5: Average session length (minutes) | K5: Maximum session length (minutes) | L5: Total time gambling (hours, 30d) | M5: Night-time play (share 0–1) | N5: Weekend play (share 0–1) | O5: Play during working hours (share 0–1) | P5: Continuous play without breaks (minutes) | Q5: Consecutive days played (days) | R5: Time-of-day shift (hours) | S5: Deposit count (count, 30d) | T5: Deposit amount (€, 30d) | U5: Deposits per session (per session) | V5: Multiple deposits in short time (max in any 12h) | W5: Deposit soon after a loss (count, 30d) | X5: Time between deposits (hours) | Y5: Deposit escalation (% vs prior 30d) | Z5: Failed / declined deposits (count, 30d) | AA5: Night-time deposits (share 0–1) | AB5: Deposit limit usage (share 0–1) | AC5: Withdrawal count & amount (count, 30d) | AD5: Withdrawal variability (€) | AE5: Cancelled / reversed withdrawals (count, 30d) | AF5: Withdrawal-to-deposit ratio (ratio) | AG5: Withdraw then redeposit (count, 30d) | AH5: Number of bets (count, 30d) | AI5: Total stake (turnover) (€, 30d) | AJ5: Average stake per bet (€) | AK5: Maximum single bet / daily stake (€) | AL5: Stake variability (CV) | AM5: Stake escalation (% per week) | AN5: Bet speed (bets/min) | AO5: Stake increase after losses (ratio) | AP5: Net loss (€, 30d) | AQ5: Loss per session / per active day (€) | AR5: Loss ratio (ratio) | AS5: Loss escalation (% vs prior 30d) | AT5: Account depletion (share of sessions) | AU5: Large single-day loss (€) | AV5: Lifetime net loss (€) | AW5: Loss vs affordability (share of monthly income) | AX5: Number of product types (count) | AY5: Share of high-risk products (share 0–1) | AZ5: Game volatility (1–5) | BA5: Game switching (games/session) | BB5: In-play betting share (share 0–1) | BC5: Product migration | BD5: Limits set | BE5: Limit increases (count, 90d) | BF5: Limit removals (count, 90d) | BG5: Limit decreases (count, 90d) | BH5: Time-outs / cool-offs (count, 90d) | BI5: Self-exclusions (count, lifetime) | BJ5: Time to self-exclusion (days (blank = never)) | BK5: Reality check dismissals (seconds) | BL5: RG page / self-test use (count, 90d) | BM5: National self-exclusion match | BN5: Number of payment methods (count) | BO5: New payment methods added (count, 30d) | BP5: Registered cards (count) | BQ5: Payment method type | BR5: Third-party payment method | BS5: Bonus usage rate (share 0–1) | BT5: Bonus begging (count, 90d) | BU5: Response to promotions (share 0–1) | BV5: Reward / free-spin chasing (share 0–1) | BW5: Customer service contacts (count, 90d) | BX5: Complaints (count, 90d) | BY5: Harm language in chat / email (messages, 90d) | BZ5: Third-party contacts | CA5: RG interaction outcomes | CB5: Self-reported screening (0–27 (blank = not taken)) | CC5: Login frequency (per day) | CD5: Logins without betting (share 0–1) | CE5: Device / channel (share 0–1) | CF5: Account detail changes (count, 90d) | CG5: Multiple brand accounts (count) | CH5: Change vs own baseline (% vs baseline) | CI5: Escalation slope (% per week) | CJ5: Early behaviour window (€ stake, first 30d) | CK5: Look-back window (months) | CL5: Behaviour volatility (CV of weekly spend) | CM5: Simulated outcome: RG case (1) / not (0) – TEST ONLY
A6: P001 | B6: 39 | C6: Male | D6: Denmark | E6: 444 | F6: Medium | G6: No | H6: 7 | I6: 9 | J6: 49.3 | K6: 110 | L6: 7.4 | M6: 0.17 | N6: 0.33 | O6: 0.17 | P6: 83 | Q6: 6 | R6: 0.5 | S6: 8 | T6: 216 | U6: 0.89 | V6: 1 | W6: 0 | X6: 72.2 | Y6: 67 | Z6: 0 | AA6: 0.22 | AB6: 0.31 | AC6: 7 | AD6: 123 | AE6: 0 | AF6: 0.47 | AG6: 0 | AH6: 173 | AI6: 136 | AJ6: 0.79 | AK6: 7 | AL6: 0.82 | AM6: 2.4 | AN6: 4.5 | AO6: 0.83 | AP6: 134 | AQ6: 19 | AR6: 0.985 | AS6: 32 | AT6: 0.18 | AU6: 45 | AV6: 1273 | AW6: 0.045 | AX6: 1 | AY6: 0.73 | AZ6: 1.2 | BA6: 2.7 | BB6: 0.08 | BC6: No | BD6: No | BE6: 1 | BF6: 0 | BG6: 0 | BH6: 1 | BI6: 0 | BK6: 6 | BL6: 0 | BM6: No | BN6: 3 | BO6: 0 | BP6: 1 | BQ6: E-wallet | BR6: No | BS6: 0.33 | BT6: 0 | BU6: 0.17 | BV6: 0.23 | BW6: 2 | BX6: 0 | BY6: 0 | BZ6: No | CA6: None | CC6: 1.5 | CD6: 0.08 | CE6: 0.42 | CF6: 0 | CG6: 1 | CH6: 44 | CI6: 1.4 | CJ6: 147 | CK6: 6 | CL6: 0.47 | CM6: 0
A7: P002 | B7: 31 | C7: Male | D7: Denmark | E7: 774 | F7: Medium | G7: No | H7: 9 | I7: 9 | J7: 28.4 | K7: 59 | L7: 4.3 | M7: 0.05 | N7: 0.26 | O7: 0.22 | P7: 41 | Q7: 1 | R7: 0.4 | S7: 19 | T7: 326 | U7: 2.11 | V7: 1 | W7: 1 | X7: 49.8 | Y7: -17 | Z7: 0 | AA7: 0.13 | AB7: 0.56 | AC7: 3 | AD7: 44 | AE7: 0 | AF7: 0.44 | AG7: 0 | AH7: 286 | AI7: 368 | AJ7: 1.29 | AK7: 9 | AL7: 0.64 | AM7: 4.3 | AN7: 3.7 | AO7: 1.16 | AP7: 195 | AQ7: 22 | AR7: 0.53 | AS7: -40 | AT7: 0.23 | AU7: 97 | AV7: 586 | AW7: 0.065 | AX7: 2 | AY7: 0.91 | AZ7: 2.4 | BA7: 1.8 | BB7: 0.34 | BC7: No | BD7: No | BE7: 0 | BF7: 0 | BG7: 1 | BH7: 0 | BI7: 0 | BK7: 7.1 | BL7: 0 | BM7: No | BN7: 2 | BO7: 0 | BP7: 3 | BQ7: E-wallet | BR7: No | BS7: 0.21 | BT7: 0 | BU7: 0.1 | BV7: 0.22 | BW7: 1 | BX7: 1 | BY7: 0 | BZ7: No | CA7: Improved | CB7: 1 | CC7: 1.1 | CD7: 0.22 | CE7: 0.37 | CF7: 0 | CG7: 1 | CH7: 8 | CI7: 1.8 | CJ7: 288 | CK7: 6 | CL7: 0.43 | CM7: 0
A8: P003 | B8: 45 | C8: Male | D8: Spain | E8: 422 | F8: Medium | G8: No | H8: 5 | I8: 5 | J8: 41.2 | K8: 96 | L8: 3.4 | M8: 0.04 | N8: 0.39 | O8: 0.16 | P8: 75 | Q8: 3 | R8: 1 | S8: 3 | T8: 37 | U8: 0.6 | V8: 1 | W8: 2 | X8: 195.3 | Y8: -30 | Z8: 0 | AA8: 0.1 | AB8: 0.47 | AC8: 4 | AD8: 39 | AE8: 0 | AF8: 0.86 | AG8: 0 | AH8: 180 | AI8: 144 | AJ8: 0.8 | AK8: 5 | AL8: 0.7 | AM8: -3.9 | AN8: 4.5 | AO8: 0.81 | AP8: 5 | AQ8: 1 | AR8: 0.035 | AS8: -1 | AT8: 0.05 | AU8: 1 | AV8: 47 | AW8: 0.002 | AX8: 1 | AY8: 0.26 | AZ8: 3.2 | BA8: 1 | BB8: 0.11 | BC8: No | BD8: Yes | BE8: 0 | BF8: 0 | BG8: 0 | BH8: 0 | BI8: 0 | BK8: 8 | BL8: 0 | BM8: No | BN8: 1 | BO8: 0 | BP8: 1 | BQ8: Card | BR8: Yes | BS8: 0.35 | BT8: 0 | BU8: 0.31 | BV8: 0.28 | BW8: 1 | BX8: 0 | BY8: 0 | BZ8: No | CA8: Improved | CB8: 3 | CC8: 1.7 | CD8: 0.24 | CE8: 0.6 | CF8: 0 | CG8: 1 | CH8: 2 | CI8: 3.9 | CJ8: 100 | CK8: 6 | CL8: 0.25 | CM8: 0
A9: P004 | B9: 70 | C9: Female | D9: Spain | E9: 141 | F9: High | G9: No | H9: 2 | I9: 2 | J9: 48 | K9: 95 | L9: 1.6 | M9: 0.17 | N9: 0.26 | O9: 0.13 | P9: 67 | Q9: 2 | R9: 0.8 | S9: 1 | T9: 34 | U9: 0.5 | V9: 2 | W9: 0 | X9: 759.9 | Y9: -41 | Z9: 1 | AA9: 0.17 | AB9: 0.01 | AC9: 5 | AD9: 123 | AE9: 1 | AF9: 0.82 | AG9: 0 | AH9: 55 | AI9: 47 | AJ9: 0.85 | AK9: 7 | AL9: 0.37 | AM9: -2.6 | AN9: 3.8 | AO9: 0.63 | AP9: 8 | AQ9: 4 | AR9: 0.17 | AS9: 38 | AT9: 0 | AU9: 2 | AV9: 22 | AW9: 0.001 | AX9: 1 | AY9: 0.41 | AZ9: 2.5 | BA9: 1 | BB9: 0.02 | BC9: No | BD9: No | BE9: 0 | BF9: 0 | BG9: 0 | BH9: 0 | BI9: 0 | BK9: 6.7 | BL9: 1 | BM9: No | BN9: 1 | BO9: 0 | BP9: 0 | BQ9: Bank transfer | BR9: No | BS9: 0.14 | BT9: 0 | BU9: 0.26 | BV9: 0.34 | BW9: 1 | BX9: 0 | BY9: 0 | BZ9: No | CA9: None | CC9: 0 | CD9: 0 | CE9: 0.88 | CF9: 0 | CG9: 2 | CH9: -35 | CI9: -3.5 | CJ9: 28 | CK9: 4 | CL9: 0.32 | CM9: 0
A10: P005 | B10: 36 | C10: Female | D10: Spain | E10: 259 | F10: Medium | G10: No | H10: 1 | I10: 1 | J10: 29.5 | K10: 80 | L10: 0.5 | M10: 0.11 | N10: 0.21 | O10: 0.08 | P10: 65 | Q10: 1 | R10: 0.5 | S10: 1 | T10: 14 | U10: 1 | V10: 1 | W10: 1 | X10: 886.8 | Y10: 32 | Z10: 0 | AA10: 0.12 | AB10: 0.35 | AC10: 6 | AD10: 83 | AE10: 0 | AF10: 0.66 | AG10: 0 | AH10: 29 | AI10: 6 | AJ10: 0.21 | AK10: 1 | AL10: 0.43 | AM10: 2.5 | AN10: 4.2 | AO10: 0.89 | AP10: 6 | AQ10: 6 | AR10: 1 | AS10: -16 | AT10: 0.13 | AU10: 1 | AV10: 18 | AW10: 0.002 | AX10: 1 | AY10: 0.35 | AZ10: 2 | BA10: 1.3 | BB10: 0.23 | BC10: No | BD10: No | BE10: 0 | BF10: 0 | BG10: 0 | BH10: 0 | BI10: 0 | BK10: 5.9 | BL10: 1 | BM10: No | BN10: 1 | BO10: 0 | BP10: 1 | BQ10: E-wallet | BR10: No | BS10: 0.4 | BT10: 0 | BU10: 0.32 | BV10: 0.13 | BW10: 0 | BX10: 0 | BY10: 0 | BZ10: No | CA10: None | CC10: 1.9 | CD10: 0.07 | CE10: 0.79 | CF10: 0 | CG10: 1 | CH10: -2 | CI10: 2.6 | CJ10: 7 | CK10: 6 | CL10: 0.2 | CM10: 0
A11: P006 | B11: 42 | C11: Female | D11: UK | E11: 1448 | F11: Medium | G11: No | H11: 4 | I11: 4 | J11: 44.2 | K11: 53 | L11: 2.9 | M11: 0.04 | N11: 0.44 | O11: 0.02 | P11: 45 | Q11: 1 | R11: 2.2 | S11: 1 | T11: 26 | U11: 0.25 | V11: 1 | W11: 0 | X11: 822.7 | Y11: 43 | Z11: 0 | AA11: 0.05 | AB11: 0.01 | AC11: 4 | AD11: 72 | AE11: 0 | AF11: 0.98 | AG11: 0 | AH11: 141 | AI11: 137 | AJ11: 0.97 | AK11: 5 | AL11: 0.28 | AM11: -2.8 | AN11: 3 | AO11: 0.65 | AP11: 6 | AQ11: 2 | AR11: 0.044 | AS11: -19 | AT11: 0.04 | AU11: 2 | AV11: 187 | AW11: 0.002 | AX11: 1 | AY11: 0.44 | AZ11: 2.5 | BA11: 2.5 | BB11: 0.12 | BC11: No | BD11: Yes | BE11: 0 | BF11: 0 | BG11: 1 | BH11: 0 | BI11: 0 | BK11: 7.6 | BL11: 0 | BM11: No | BN11: 1 | BO11: 0 | BP11: 0 | BQ11: Card | BR11: No | BS11: 0.11 | BT11: 0 | BU11: 0.18 | BV11: 0.25 | BW11: 0 | BX11: 0 | BY11: 0 | BZ11: No | CA11: None | CC11: 0.7 | CD11: 0 | CE11: 0.53 | CF11: 0 | CG11: 1 | CH11: -28 | CI11: 4.5 | CJ11: 44 | CK11: 6 | CL11: 0.3 | CM11: 0
A12: P007 | B12: 44 | C12: Male | D12: Malta | E12: 576 | F12: Medium | G12: No | H12: 16 | I12: 16 | J12: 34.3 | K12: 66 | L12: 9.2 | M12: 0.2 | N12: 0.37 | O12: 0.16 | P12: 44 | Q12: 3 | R12: 0.4 | S12: 26 | T12: 1616 | U12: 1.62 | V12: 1 | W12: 1 | X12: 22.5 | Y12: 22 | Z12: 0 | AA12: 0.21 | AB12: 0.62 | AC12: 5 | AD12: 35 | AE12: 0 | AF12: 0.53 | AG12: 1 | AH12: 898 | AI12: 1728 | AJ12: 1.92 | AK12: 20 | AL12: 0.84 | AM12: -2.8 | AN12: 4.7 | AO12: 1.36 | AP12: 982 | AQ12: 61 | AR12: 0.568 | AS12: 23 | AT12: 0.14 | AU12: 259 | AV12: 3293 | AW12: 0.327 | AX12: 1 | AY12: 0.56 | AZ12: 1.6 | BA12: 2.9 | BB12: 0.37 | BC12: No | BD12: No | BE12: 0 | BF12: 0 | BG12: 1 | BH12: 0 | BI12: 0 | BK12: 7.6 | BL12: 2 | BM12: No | BN12: 1 | BO12: 0 | BP12: 2 | BQ12: Bank transfer | BR12: No | BS12: 0.2 | BT12: 0 | BU12: 0.16 | BV12: 0.26 | BW12: 1 | BX12: 0 | BY12: 0 | BZ12: No | CA12: None | CC12: 1 | CD12: 0.21 | CE12: 0.55 | CF12: 0 | CG12: 2 | CH12: 26 | CI12: 4.2 | CJ12: 1687 | CK12: 6 | CL12: 0.22 | CM12: 0
A13: P008 | B13: 39 | C13: Male | D13: Spain | E13: 865 | F13: Medium | G13: No | H13: 21 | I13: 39 | J13: 21.9 | K13: 69 | L13: 14.2 | M13: 0.4 | N13: 0.32 | O13: 0.17 | P13: 59 | Q13: 5 | R13: 1.3 | S13: 96 | T13: 7753 | U13: 2.46 | V13: 3 | W13: 3 | X13: 6.4 | Y13: 29 | Z13: 1 | AA13: 0.41 | AB13: 0.76 | AC13: 0 | AD13: 0 | AE13: 1 | AF13: 0.29 | AG13: 1 | AH13: 2794 | AI13: 6190 | AJ13: 2.22 | AK13: 17 | AL13: 1.15 | AM13: -0.5 | AN13: 3.3 | AO13: 1.1 | AP13: 5990 | AQ13: 285 | AR13: 0.968 | AS13: 18 | AT13: 0.31 | AU13: 2873 | AV13: 44752 | AW13: 1.997 | AX13: 1 | AY13: 1 | AZ13: 3.3 | BA13: 2.7 | BB13: 0.45 | BC13: No | BD13: Yes | BE13: 2 | BF13: 1 | BG13: 0 | BH13: 1 | BI13: 1 | BJ13: 111 | BK13: 5.4 | BL13: 2 | BM13: No | BN13: 3 | BO13: 0 | BP13: 3 | BQ13: Card | BR13: No | BS13: 0.16 | BT13: 1 | BU13: 0.43 | BV13: 0.38 | BW13: 3 | BX13: 1 | BY13: 2 | BZ13: No | CA13: Improved | CB13: 11 | CC13: 1.6 | CD13: 0.27 | CE13: 0.74 | CF13: 0 | CG13: 2 | CH13: 48 | CI13: 11.4 | CJ13: 7303 | CK13: 6 | CL13: 0.56 | CM13: 1
A14: P009 | B14: 43 | C14: Male | D14: Spain | E14: 661 | F14: Medium | G14: No | H14: 11 | I14: 18 | J14: 31.6 | K14: 59 | L14: 9.5 | M14: 0.17 | N14: 0.39 | O14: 0.05 | P14: 42 | Q14: 5 | R14: 0.6 | S14: 10 | T14: 638 | U14: 0.56 | V14: 1 | W14: 0 | X14: 65.3 | Y14: -18 | Z14: 1 | AA14: 0.13 | AB14: 0.3 | AC14: 1 | AD14: 18 | AE14: 0 | AF14: 0.63 | AG14: 1 | AH14: 550 | AI14: 815 | AJ14: 1.48 | AK14: 9 | AL14: 0.16 | AM14: -2.2 | AN14: 4.1 | AO14: 0.99 | AP14: 292 | AQ14: 27 | AR14: 0.358 | AS14: -7 | AT14: 0.3 | AU14: 76 | AV14: 1364 | AW14: 0.097 | AX14: 1 | AY14: 0.53 | AZ14: 2.8 | BA14: 2.4 | BB14: 0.06 | BC14: No | BD14: Yes | BE14: 0 | BF14: 0 | BG14: 0 | BH14: 0 | BI14: 0 | BK14: 5.7 | BL14: 0 | BM14: No | BN14: 2 | BO14: 0 | BP14: 1 | BQ14: Card | BR14: No | BS14: 0.07 | BT14: 0 | BU14: 0.13 | BV14: 0.46 | BW14: 0 | BX14: 0 | BY14: 0 | BZ14: No | CA14: None | CC14: 2 | CD14: 0.28 | CE14: 0.71 | CF14: 1 | CG14: 1 | CH14: -19 | CI14: 0.5 | CJ14: 664 | CK14: 6 | CL14: 0.14 | CM14: 0
A15: P010 | B15: 44 | C15: Male | D15: Spain | E15: 1206 | F15: Medium | G15: No | H15: 8 | I15: 12 | J15: 38.9 | K15: 65 | L15: 7.8 | M15: 0.08 | N15: 0.41 | O15: 0.04 | P15: 57 | Q15: 1 | R15: 0.2 | S15: 1 | T15: 25 | U15: 0.08 | V15: 1 | W15: 0 | X15: 712.6 | Y15: 23 | Z15: 0 | AA15: 0 | AB15: 0.01 | AC15: 6 | AD15: 47 | AE15: 0 | AF15: 0.43 | AG15: 0 | AH15: 286 | AI15: 162 | AJ15: 0.57 | AK15: 4 | AL15: 0.3 | AM15: -0.9 | AN15: 2.8 | AO15: 0.99 | AP15: 17 | AQ15: 2 | AR15: 0.105 | AS15: 14 | AT15: 0 | AU15: 6 | AV15: 190 | AW15: 0.006 | AX15: 2 | AY15: 0.39 | AZ15: 2.9 | BA15: 1 | BB15: 0.11 | BC15: No | BD15: Yes | BE15: 0 | BF15: 0 | BG15: 1 | BH15: 0 | BI15: 0 | BK15: 2.8 | BL15: 2 | BM15: No | BN15: 2 | BO15: 0 | BP15: 2 | BQ15: Bank transfer | BR15: No | BS15: 0.32 | BT15: 0 | BU15: 0.2 | BV15: 0 | BW15: 1 | BX15: 0 | BY15: 0 | BZ15: No | CA15: None | CB15: 0 | CC15: 1.8 | CD15: 0.09 | CE15: 0.34 | CF15: 0 | CG15: 1 | CH15: -15 | CI15: -1 | CJ15: 136 | CK15: 6 | CL15: 0.43 | CM15: 1
A16: P011 | B16: 46 | C16: Female | D16: Denmark | E16: 156 | F16: Low | G16: No | H16: 7 | I16: 12 | J16: 32.9 | K16: 72 | L16: 6.6 | M16: 0.18 | N16: 0.33 | O16: 0.15 | P16: 72 | Q16: 6 | R16: 0.9 | S16: 22 | T16: 564 | U16: 1.83 | V16: 1 | W16: 1 | X16: 40.2 | Y16: -3 | Z16: 0 | AA16: 0.15 | AB16: 0.52 | AC16: 5 | AD16: 46 | AE16: 0 | AF16: 0.63 | AG16: 0 | AH16: 697 | AI16: 642 | AJ16: 0.92 | AK16: 5 | AL16: 0.99 | AM16: 3.6 | AN16: 4.8 | AO16: 0.83 | AP16: 246 | AQ16: 35 | AR16: 0.383 | AS16: 22 | AT16: 0.2 | AU16: 111 | AV16: 864 | AW16: 0.164 | AX16: 1 | AY16: 0.79 | AZ16: 2.5 | BA16: 3.5 | BB16: 0.23 | BC16: Yes | BD16: Yes | BE16: 0 | BF16: 0 | BG16: 0 | BH16: 0 | BI16: 0 | BK16: 9.6 | BL16: 2 | BM16: No | BN16: 1 | BO16: 0 | BP16: 1 | BQ16: Card | BR16: No | BS16: 0.81 | BT16: 0 | BU16: 0.16 | BV16: 0.22 | BW16: 0 | BX16: 0 | BY16: 0 | BZ16: No | CA16: None | CB16: 4 | CC16: 1.2 | CD16: 0.16 | CE16: 0.36 | CF16: 0 | CG16: 1 | CH16: 23 | CI16: 4.6 | CJ16: 691 | CK16: 5 | CL16: 0.3 | CM16: 1
A17: P012 | B17: 45 | C17: Female | D17: Spain | E17: 426 | F17: Medium | G17: No | H17: 15 | I17: 19 | J17: 26.4 | K17: 44 | L17: 8.4 | M17: 0.19 | N17: 0.05 | O17: 0.06 | P17: 41 | Q17: 1 | R17: 0.4 | S17: 33 | T17: 2170 | U17: 1.74 | V17: 2 | W17: 2 | X17: 16.2 | Y17: 64 | Z17: 0 | AA17: 0.09 | AB17: 0.32 | AC17: 3 | AD17: 71 | AE17: 0 | AF17: 0.35 | AG17: 0 | AH17: 1158 | AI17: 1543 | AJ17: 1.33 | AK17: 9 | AL17: 0.63 | AM17: 2 | AN17: 4.3 | AO17: 0.83 | AP17: 1641 | AQ17: 109 | AR17: 1.064 | AS17: 23 | AT17: 0.23 | AU17: 486 | AV17: 5436 | AW17: 0.547 | AX17: 2 | AY17: 0.49 | AZ17: 3.5 | BA17: 1.9 | BB17: 0.02 | BC17: Yes | BD17: No | BE17: 0 | BF17: 0 | BG17: 0 | BH17: 0 | BI17: 0 | BK17: 7.4 | BL17: 0 | BM17: No | BN17: 3 | BO17: 1 | BP17: 2 | BQ17: Bank transfer | BR17: No | BS17: 0.15 | BT17: 0 | BU17: 0.18 | BV17: 0.07 | BW17: 2 | BX17: 0 | BY17: 0 | BZ17: No | CA17: None | CC17: 2.7 | CD17: 0.12 | CE17: 0.91 | CF17: 0 | CG17: 1 | CH17: 9 | CI17: 3.1 | CJ17: 1635 | CK17: 6 | CL17: 0.34 | CM17: 0
A18: P013 | B18: 31 | C18: Male | D18: Malta | E18: 878 | F18: High | G18: No | H18: 8 | I18: 14 | J18: 29.4 | K18: 62 | L18: 6.9 | M18: 0.09 | N18: 0.23 | O18: 0.07 | P18: 48 | Q18: 5 | R18: 2.1 | S18: 21 | T18: 1003 | U18: 1.5 | V18: 1 | W18: 1 | X18: 37.5 | Y18: 56 | Z18: 1 | AA18: 0.09 | AB18: 0.56 | AC18: 3 | AD18: 81 | AE18: 0 | AF18: 0.49 | AG18: 0 | AH18: 602 | AI18: 1359 | AJ18: 2.26 | AK18: 16 | AL18: 0.42 | AM18: -0.8 | AN18: 2.8 | AO18: 1.11 | AP18: 695 | AQ18: 87 | AR18: 0.511 | AS18: -1 | AT18: 0.05 | AU18: 219 | AV18: 5487 | AW18: 0.116 | AX18: 2 | AY18: 0.43 | AZ18: 3.9 | BA18: 2.8 | BB18: 0.06 | BC18: No | BD18: Yes | BE18: 0 | BF18: 0 | BG18: 0 | BH18: 0 | BI18: 0 | BK18: 6.4 | BL18: 0 | BM18: No | BN18: 1 | BO18: 0 | BP18: 3 | BQ18: Card | BR18: No | BS18: 0.15 | BT18: 0 | BU18: 0.25 | BV18: 0.22 | BW18: 1 | BX18: 0 | BY18: 0 | BZ18: No | CA18: None | CC18: 1.7 | CD18: 0.22 | CE18: 0.65 | CF18: 0 | CG18: 1 | CH18: 37 | CI18: 5.8 | CJ18: 1342 | CK18: 6 | CL18: 0.5 | CM18: 0
A19: P014 | B19: 47 | C19: Female | D19: Ontario | E19: 1203 | F19: Medium | G19: No | H19: 4 | I19: 4 | J19: 53 | K19: 158 | L19: 3.5 | M19: 0 | N19: 0.25 | O19: 0.01 | P19: 150 | Q19: 1 | R19: 0.2 | S19: 4 | T19: 194 | U19: 1 | V19: 1 | W19: 1 | X19: 202 | Y19: -16 | Z19: 1 | AA19: 0 | AB19: 0.19 | AC19: 4 | AD19: 78 | AE19: 0 | AF19: 0.67 | AG19: 0 | AH19: 113 | AI19: 176 | AJ19: 1.56 | AK19: 17 | AL19: 0.37 | AM19: 0 | AN19: 2.1 | AO19: 0.7 | AP19: 103 | AQ19: 26 | AR19: 0.585 | AS19: -10 | AT19: 0.02 | AU19: 16 | AV19: 1279 | AW19: 0.034 | AX19: 1 | AY19: 0.8 | AZ19: 2 | BA19: 1.6 | BB19: 0.25 | BC19: No | BD19: Yes | BE19: 0 | BF19: 0 | BG19: 0 | BH19: 0 | BI19: 0 | BK19: 8.1 | BL19: 0 | BM19: No | BN19: 1 | BO19: 0 | BP19: 0 | BQ19: Bank transfer | BR19: No | BS19: 0.23 | BT19: 0 | BU19: 0.28 | BV19: 0.13 | BW19: 0 | BX19: 0 | BY19: 0 | BZ19: No | CA19: None | CB19: 0 | CC19: 0.6 | CD19: 0 | CE19: 0.76 | CF19: 0 | CG19: 1 | CH19: -1 | CI19: -9.7 | CJ19: 90 | CK19: 6 | CL19: 0.24 | CM19: 0
A20: P015 | B20: 43 | C20: Female | D20: Spain | E20: 694 | F20: High | G20: No | H20: 7 | I20: 7 | J20: 37.7 | K20: 93 | L20: 4.4 | M20: 0.12 | N20: 0.2 | O20: 0.16 | P20: 60 | Q20: 1 | R20: 1.4 | S20: 5 | T20: 199 | U20: 0.71 | V20: 1 | W20: 0 | X20: 160.1 | Y20: 29 | Z20: 0 | AA20: 0.04 | AB20: 0.23 | AC20: 2 | AD20: 69 | AE20: 0 | AF20: 0.71 | AG20: 0 | AH20: 242 | AI20: 293 | AJ20: 1.21 | AK20: 5 | AL20: 0.58 | AM20: 1.6 | AN20: 4.6 | AO20: 1.05 | AP20: 109 | AQ20: 16 | AR20: 0.372 | AS20: 6 | AT20: 0.33 | AU20: 36 | AV20: 1359 | AW20: 0.018 | AX20: 1 | AY20: 0.32 | AZ20: 3.2 | BA20: 1.6 | BB20: 0 | BC20: No | BD20: Yes | BE20: 0 | BF20: 0 | BG20: 2 | BH20: 0 | BI20: 0 | BK20: 5 | BL20: 0 | BM20: No | BN20: 1 | BO20: 0 | BP20: 2 | BQ20: Card | BR20: No | BS20: 0.36 | BT20: 0 | BU20: 0.19 | BV20: 0.7 | BW20: 2 | BX20: 0 | BY20: 0 | BZ20: No | CA20: None | CC20: 1.4 | CD20: 0.2 | CE20: 0.63 | CF20: 0 | CG20: 1 | CH20: 13 | CI20: -0.1 | CJ20: 250 | CK20: 6 | CL20: 0.65 | CM20: 0
A21: P016 | B21: 27 | C21: Male | D21: UK | E21: 1055 | F21: Medium | G21: No | H21: 11 | I21: 16 | J21: 42.1 | K21: 83 | L21: 11.2 | M21: 0.11 | N21: 0.32 | O21: 0.21 | P21: 83 | Q21: 5 | R21: 0.7 | S21: 22 | T21: 1636 | U21: 1.38 | V21: 2 | W21: 3 | X21: 35.8 | Y21: 53 | Z21: 1 | AA21: 0.14 | AB21: 0.72 | AC21: 5 | AD21: 13 | AE21: 0 | AF21: 0.45 | AG21: 0 | AH21: 524 | AI21: 1383 | AJ21: 2.64 | AK21: 21 | AL21: 0.76 | AM21: 6.8 | AN21: 6.5 | AO21: 1.34 | AP21: 1147 | AQ21: 104 | AR21: 0.829 | AS21: 59 | AT21: 0.35 | AU21: 522 | AV21: 17428 | AW21: 0.382 | AX21: 1 | AY21: 0.49 | AZ21: 2.2 | BA21: 3 | BB21: 0.41 | BC21: No | BD21: No | BE21: 1 | BF21: 0 | BG21: 0 | BH21: 0 | BI21: 0 | BK21: 3 | BL21: 2 | BM21: No | BN21: 3 | BO21: 1 | BP21: 2 | BQ21: E-wallet | BR21: No | BS21: 0.27 | BT21: 0 | BU21: 0.49 | BV21: 0.36 | BW21: 5 | BX21: 0 | BY21: 0 | BZ21: No | CA21: No change | CB21: 10 | CC21: 1.9 | CD21: 0.22 | CE21: 0.87 | CF21: 0 | CG21: 1 | CH21: 3 | CI21: 7.1 | CJ21: 1099 | CK21: 6 | CL21: 0.75 | CM21: 0
A22: P017 | B22: 53 | C22: Female | D22: Denmark | E22: 1202 | F22: Medium | G22: No | H22: 1 | I22: 2 | J22: 56.1 | K22: 93 | L22: 1.9 | M22: 0.01 | N22: 0.42 | O22: 0.2 | P22: 68 | Q22: 1 | R22: 0.6 | S22: 1 | T22: 37 | U22: 0.5 | V22: 1 | W22: 1 | X22: 938.6 | Y22: 16 | Z22: 0 | AA22: 0.05 | AB22: 0.28 | AC22: 5 | AD22: 0 | AE22: 0 | AF22: 0.87 | AG22: 0 | AH22: 10 | AI22: 5 | AJ22: 0.5 | AK22: 4 | AL22: 0.19 | AM22: -10.9 | AN22: 1.4 | AO22: 0.61 | AP22: 8 | AQ22: 8 | AR22: 1.6 | AS22: -10 | AT22: 0.01 | AU22: 2 | AV22: 216 | AW22: 0.003 | AX22: 1 | AY22: 0.3 | AZ22: 1 | BA22: 1 | BB22: 0.1 | BC22: No | BD22: No | BE22: 0 | BF22: 0 | BG22: 1 | BH22: 0 | BI22: 0 | BK22: 7.4 | BL22: 0 | BM22: No | BN22: 1 | BO22: 0 | BP22: 0 | BQ22: E-wallet | BR22: No | BS22: 0.14 | BT22: 0 | BU22: 0.34 | BV22: 0.33 | BW22: 1 | BX22: 0 | BY22: 0 | BZ22: No | CA22: None | CB22: 0 | CC22: 1.2 | CD22: 0 | CE22: 0.4 | CF22: 0 | CG22: 1 | CH22: -17 | CI22: -8.8 | CJ22: 2 | CK22: 6 | CL22: 0.2 | CM22: 0
A23: P018 | B23: 36 | C23: Female | D23: Ontario | E23: 967 | F23: Low | G23: No | H23: 6 | I23: 8 | J23: 44.4 | K23: 82 | L23: 5.9 | M23: 0.09 | N23: 0.25 | O23: 0.04 | P23: 43 | Q23: 1 | R23: 1.4 | S23: 2 | T23: 95 | U23: 0.25 | V23: 1 | W23: 0 | X23: 395.1 | Y23: -35 | Z23: 1 | AA23: 0.09 | AB23: 0.19 | AC23: 4 | AD23: 44 | AE23: 0 | AF23: 0.44 | AG23: 1 | AH23: 339 | AI23: 723 | AJ23: 2.13 | AK23: 13 | AL23: 0.44 | AM23: -3.8 | AN23: 2.4 | AO23: 0.73 | AP23: 62 | AQ23: 10 | AR23: 0.086 | AS23: -13 | AT23: 0.14 | AU23: 26 | AV23: 715 | AW23: 0.041 | AX23: 1 | AY23: 0.21 | AZ23: 2.9 | BA23: 1.4 | BB23: 0.13 | BC23: No | BD23: No | BE23: 0 | BF23: 0 | BG23: 0 | BH23: 0 | BI23: 0 | BK23: 6.2 | BL23: 0 | BM23: No | BN23: 2 | BO23: 0 | BP23: 0 | BQ23: Card | BR23: No | BS23: 0 | BT23: 0 | BU23: 0.03 | BV23: 0.36 | BW23: 0 | BX23: 0 | BY23: 0 | BZ23: No | CA23: Improved | CC23: 1.2 | CD23: 0.05 | CE23: 0.64 | CF23: 1 | CG23: 1 | CH23: -34 | CI23: -1.6 | CJ23: 447 | CK23: 6 | CL23: 0.39 | CM23: 1
A24: P019 | B24: 63 | C24: Male | D24: UK | E24: 1230 | F24: Medium | G24: No | H24: 1 | I24: 1 | J24: 71.8 | K24: 172 | L24: 1.2 | M24: 0.13 | N24: 0.19 | O24: 0.01 | P24: 172 | Q24: 1 | R24: 0.1 | S24: 1 | T24: 22 | U24: 1 | V24: 1 | W24: 1 | X24: 843.4 | Y24: -12 | Z24: 2 | AA24: 0.22 | AB24: 0.25 | AC24: 5 | AD24: 41 | AE24: 0 | AF24: 0.97 | AG24: 1 | AH24: 9 | AI24: 6 | AJ24: 0.67 | AK24: 2 | AL24: 0.1 | AM24: -8.6 | AN24: 2.6 | AO24: 0.5 | AP24: 5 | AQ24: 5 | AR24: 0.833 | AS24: -80 | AT24: 0 | AU24: 0 | AV24: 50 | AW24: 0.002 | AX24: 1 | AY24: 0 | AZ24: 1.8 | BA24: 1.1 | BB24: 0.08 | BC24: No | BD24: No | BE24: 0 | BF24: 0 | BG24: 0 | BH24: 0 | BI24: 0 | BK24: 7.6 | BL24: 1 | BM24: No | BN24: 1 | BO24: 0 | BP24: 0 | BQ24: E-wallet | BR24: No | BS24: 0.02 | BT24: 0 | BU24: 0.01 | BV24: 0.01 | BW24: 1 | BX24: 1 | BY24: 0 | BZ24: No | CA24: None | CB24: 0 | CC24: 0 | CD24: 0.08 | CE24: 0.68 | CF24: 0 | CG24: 1 | CH24: -42 | CI24: -11.1 | CJ24: 2 | CK24: 6 | CL24: 0.05 | CM24: 0
A25: P020 | B25: 52 | C25: Female | D25: Denmark | E25: 1426 | F25: High | G25: No | H25: 1 | I25: 1 | J25: 31.5 | K25: 53 | L25: 0.5 | M25: 0 | N25: 0.5 | O25: 0.14 | P25: 51 | Q25: 1 | R25: 0.1 | S25: 1 | T25: 29 | U25: 1 | V25: 1 | W25: 1 | X25: 801.2 | Y25: -40 | Z25: 0 | AA25: 0.09 | AB25: 0.08 | AC25: 6 | AD25: 47 | AE25: 0 | AF25: 0.64 | AG25: 0 | AH25: 38 | AI25: 17 | AJ25: 0.45 | AK25: 3 | AL25: 0.33 | AM25: -10.8 | AN25: 1.2 | AO25: 0.71 | AP25: 12 | AQ25: 12 | AR25: 0.706 | AS25: -9 | AT25: 0.05 | AU25: 1 | AV25: 228 | AW25: 0.002 | AX25: 1 | AY25: 0.51 | AZ25: 2.2 | BA25: 4.8 | BB25: 0.14 | BC25: No | BD25: Yes | BE25: 0 | BF25: 0 | BG25: 0 | BH25: 0 | BI25: 0 | BK25: 5 | BL25: 0 | BM25: No | BN25: 1 | BO25: 1 | BP25: 1 | BQ25: E-wallet | BR25: No | BS25: 0.27 | BT25: 0 | BU25: 0 | BV25: 0.18 | BW25: 0 | BX25: 0 | BY25: 0 | BZ25: No | CA25: None | CB25: 0 | CC25: 1.6 | CD25: 0.19 | CE25: 0.65 | CF25: 0 | CG25: 1 | CH25: -27 | CI25: -3.7 | CJ25: 11 | CK25: 6 | CL25: 0.05 | CM25: 0
A26: P021 | B26: 54 | C26: Female | D26: Malta | E26: 331 | F26: High | G26: No | H26: 10 | I26: 11 | J26: 53.9 | K26: 93 | L26: 9.9 | M26: 0 | N26: 0.25 | O26: 0.04 | P26: 65 | Q26: 1 | R26: 0.2 | S26: 12 | T26: 204 | U26: 1.09 | V26: 2 | W26: 0 | X26: 81.5 | Y26: -68 | Z26: 0 | AA26: 0 | AB26: 0 | AC26: 6 | AD26: 67 | AE26: 0 | AF26: 1.01 | AG26: 0 | AH26: 55 | AI26: 48 | AJ26: 0.87 | AK26: 5 | AL26: 0.1 | AM26: -15.3 | AN26: 3.3 | AO26: 0.5 | AP26: 12 | AQ26: 1 | AR26: 0.25 | AS26: -22 | AT26: 0 | AU26: 2 | AV26: 67 | AW26: 0.002 | AX26: 1 | AY26: 0.06 | AZ26: 1.5 | BA26: 1 | BB26: 0.19 | BC26: Yes | BD26: No | BE26: 0 | BF26: 0 | BG26: 0 | BH26: 0 | BI26: 0 | BK26: 8.1 | BL26: 0 | BM26: No | BN26: 1 | BO26: 0 | BP26: 0 | BQ26: Card | BR26: No | BS26: 0.31 | BT26: 0 | BU26: 0 | BV26: 0.26 | BW26: 0 | BX26: 0 | BY26: 0 | BZ26: No | CA26: None | CC26: 0.5 | CD26: 0 | CE26: 0.38 | CF26: 0 | CG26: 1 | CH26: -59 | CI26: -4.8 | CJ26: 20 | CK26: 6 | CL26: 0.05 | CM26: 0
A27: P022 | B27: 38 | C27: Female | D27: Ontario | E27: 653 | F27: High | G27: No | H27: 7 | I27: 8 | J27: 32.4 | K27: 76 | L27: 4.3 | M27: 0.09 | N27: 0.18 | O27: 0.12 | P27: 62 | Q27: 5 | R27: 2.2 | S27: 8 | T27: 328 | U27: 1 | V27: 2 | W27: 1 | X27: 55.8 | Y27: 6 | Z27: 0 | AA27: 0.14 | AB27: 0.38 | AC27: 4 | AD27: 13 | AE27: 0 | AF27: 0.7 | AG27: 0 | AH27: 386 | AI27: 345 | AJ27: 0.89 | AK27: 6 | AL27: 0.5 | AM27: -1.1 | AN27: 3.7 | AO27: 0.99 | AP27: 155 | AQ27: 22 | AR27: 0.449 | AS27: -24 | AT27: 0.07 | AU27: 39 | AV27: 1057 | AW27: 0.026 | AX27: 1 | AY27: 0.34 | AZ27: 2.5 | BA27: 1.8 | BB27: 0.11 | BC27: No | BD27: Yes | BE27: 0 | BF27: 0 | BG27: 0 | BH27: 0 | BI27: 0 | BK27: 7.5 | BL27: 1 | BM27: No | BN27: 1 | BO27: 0 | BP27: 1 | BQ27: Bank transfer | BR27: No | BS27: 0.24 | BT27: 0 | BU27: 0.12 | BV27: 0.25 | BW27: 0 | BX27: 0 | BY27: 0 | BZ27: No | CA27: None | CB27: 5 | CC27: 0.7 | CD27: 0.17 | CE27: 0.71 | CF27: 0 | CG27: 1 | CH27: -16 | CI27: 5.5 | CJ27: 318 | CK27: 6 | CL27: 0.33 | CM27: 0
A28: P023 | B28: 48 | C28: Male | D28: UK | E28: 342 | F28: Medium | G28: No | H28: 2 | I28: 2 | J28: 63.6 | K28: 149 | L28: 2.1 | M28: 0.05 | N28: 0.32 | O28: 0.19 | P28: 116 | Q28: 1 | R28: 0.9 | S28: 1 | T28: 41 | U28: 0.5 | V28: 1 | W28: 0 | X28: 904.6 | Y28: -34 | Z28: 2 | AA28: 0.07 | AB28: 0 | AC28: 3 | AD28: 28 | AE28: 0 | AF28: 0.85 | AG28: 1 | AH28: 69 | AI28: 14 | AJ28: 0.2 | AK28: 2 | AL28: 0.26 | AM28: 0.4 | AN28: 1.2 | AO28: 0.72 | AP28: 8 | AQ28: 4 | AR28: 0.571 | AS28: -77 | AT28: 0 | AU28: 2 | AV28: 51 | AW28: 0.003 | AX28: 1 | AY28: 0.22 | AZ28: 2.6 | BA28: 1 | BB28: 0.03 | BC28: No | BD28: No | BE28: 0 | BF28: 0 | BG28: 0 | BH28: 0 | BI28: 0 | BK28: 6.9 | BL28: 0 | BM28: No | BN28: 1 | BO28: 0 | BP28: 1 | BQ28: Bank transfer | BR28: No | BS28: 0.1 | BT28: 0 | BU28: 0.06 | BV28: 0.15 | BW28: 0 | BX28: 0 | BY28: 0 | BZ28: No | CA28: None | CC28: 0.3 | CD28: 0.18 | CE28: 0.4 | CF28: 0 | CG28: 1 | CH28: -44 | CI28: -3.3 | CJ28: 10 | CK28: 6 | CL28: 0.05 | CM28: 0
A29: P024 | B29: 20 | C29: Female | D29: UK | E29: 625 | F29: High | G29: No | H29: 11 | I29: 29 | J29: 54 | K29: 109 | L29: 26.1 | M29: 0.21 | N29: 0.34 | O29: 0.14 | P29: 91 | Q29: 7 | R29: 0.5 | S29: 45 | T29: 1522 | U29: 1.55 | V29: 1 | W29: 1 | X29: 15.2 | Y29: -11 | Z29: 0 | AA29: 0.24 | AB29: 0.37 | AC29: 3 | AD29: 53 | AE29: 0 | AF29: 0.85 | AG29: 1 | AH29: 1750 | AI29: 1387 | AJ29: 0.79 | AK29: 7 | AL29: 0.86 | AM29: 4.6 | AN29: 5.4 | AO29: 0.86 | AP29: 434 | AQ29: 39 | AR29: 0.313 | AS29: -17 | AT29: 0.28 | AU29: 139 | AV29: 7796 | AW29: 0.072 | AX29: 1 | AY29: 0.33 | AZ29: 3.9 | BA29: 3.3 | BB29: 0.18 | BC29: Yes | BD29: No | BE29: 0 | BF29: 0 | BG29: 0 | BH29: 0 | BI29: 0 | BK29: 5.6 | BL29: 0 | BM29: No | BN29: 2 | BO29: 0 | BP29: 2 | BQ29: Card | BR29: No | BS29: 0.39 | BT29: 0 | BU29: 0.32 | BV29: 0.34 | BW29: 3 | BX29: 0 | BY29: 0 | BZ29: No | CA29: None | CB29: 4 | CC29: 1.2 | CD29: 0.12 | CE29: 0.41 | CF29: 0 | CG29: 1 | CH29: 68 | CI29: -0.3 | CJ29: 732 | CK29: 6 | CL29: 0.35 | CM29: 0
A30: P025 | B30: 30 | C30: Female | D30: Ontario | E30: 8 | F30: High | G30: No | H30: 11 | I30: 21 | J30: 10.8 | K30: 18 | L30: 3.8 | M30: 0.1 | N30: 0.23 | O30: 0.09 | P30: 12 | Q30: 4 | R30: 0.5 | S30: 40 | T30: 3083 | U30: 1.9 | V30: 2 | W30: 1 | X30: 17 | Y30: -33 | Z30: 0 | AA30: 0.14 | AB30: 0.4 | AC30: 6 | AD30: 63 | AE30: 0 | AF30: 0.65 | AG30: 0 | AH30: 714 | AI30: 1249 | AJ30: 1.75 | AK30: 13 | AL30: 0.7 | AM30: 10.2 | AN30: 5.9 | AO30: 1.3 | AP30: 1485 | AQ30: 135 | AR30: 1.189 | AS30: 32 | AT30: 0.21 | AU30: 459 | AV30: 151 | AW30: 0.248 | AX30: 2 | AY30: 0.3 | AZ30: 2.7 | BA30: 1 | BB30: 0.49 | BC30: No | BD30: Yes | BE30: 0 | BF30: 0 | BG30: 1 | BH30: 0 | BI30: 0 | BK30: 1.6 | BL30: 0 | BM30: No | BN30: 1 | BO30: 0 | BP30: 2 | BQ30: Card | BR30: No | BS30: 0.48 | BT30: 0 | BU30: 0.31 | BV30: 0.09 | BW30: 2 | BX30: 0 | BY30: 0 | BZ30: No | CA30: None | CC30: 1.7 | CD30: 0.14 | CE30: 0.69 | CF30: 0 | CG30: 1 | CH30: 9 | CI30: 2.9 | CJ30: 1288 | CK30: 1 | CL30: 0.33 | CM30: 0
A31: P026 | B31: 47 | C31: Female | D31: UK | E31: 1039 | F31: High | G31: No | H31: 3 | I31: 4 | J31: 24.3 | K31: 34 | L31: 1.6 | M31: 0.05 | N31: 0.38 | O31: 0.06 | P31: 25 | Q31: 1 | R31: 0.3 | S31: 5 | T31: 175 | U31: 1.25 | V31: 2 | W31: 1 | X31: 116.1 | Y31: -24 | Z31: 0 | AA31: 0.01 | AB31: 0.67 | AC31: 2 | AD31: 36 | AE31: 0 | AF31: 0.73 | AG31: 1 | AH31: 134 | AI31: 182 | AJ31: 1.36 | AK31: 9 | AL31: 0.54 | AM31: 0.2 | AN31: 2.3 | AO31: 1.12 | AP31: 68 | AQ31: 23 | AR31: 0.374 | AS31: -26 | AT31: 0.19 | AU31: 25 | AV31: 1195 | AW31: 0.011 | AX31: 1 | AY31: 0.49 | AZ31: 1.7 | BA31: 1 | BB31: 0.32 | BC31: Yes | BD31: No | BE31: 0 | BF31: 0 | BG31: 0 | BH31: 0 | BI31: 0 | BK31: 5.9 | BL31: 1 | BM31: No | BN31: 1 | BO31: 0 | BP31: 1 | BQ31: Card | BR31: No | BS31: 0.34 | BT31: 0 | BU31: 0.21 | BV31: 0.13 | BW31: 1 | BX31: 0 | BY31: 0 | BZ31: No | CA31: None | CB31: 0 | CC31: 1.6 | CD31: 0.04 | CE31: 0.79 | CF31: 0 | CG31: 2 | CH31: 0 | CI31: 2.3 | CJ31: 153 | CK31: 6 | CL31: 0.48 | CM31: 0
A32: P027 | B32: 36 | C32: Female | D32: UK | E32: 357 | F32: Low | G32: No | H32: 1 | I32: 1 | J32: 55.6 | K32: 96 | L32: 0.9 | M32: 0 | N32: 0.25 | O32: 0.04 | P32: 81 | Q32: 1 | R32: 0.2 | S32: 1 | T32: 22 | U32: 1 | V32: 1 | W32: 0 | X32: 450.9 | Y32: -22 | Z32: 0 | AA32: 0 | AB32: 0.2 | AC32: 5 | AD32: 105 | AE32: 0 | AF32: 1.12 | AG32: 0 | AH32: 5 | AI32: 1 | AJ32: 0.2 | AK32: 1 | AL32: 0.1 | AM32: -14.7 | AN32: 1.8 | AO32: 0.5 | AP32: 6 | AQ32: 6 | AR32: 6 | AS32: -69 | AT32: 0 | AU32: 2 | AV32: 55 | AW32: 0.004 | AX32: 1 | AY32: 0.59 | AZ32: 2.3 | BA32: 1 | BB32: 0 | BC32: No | BD32: No | BE32: 0 | BF32: 0 | BG32: 0 | BH32: 0 | BI32: 0 | BK32: 9.5 | BL32: 0 | BM32: No | BN32: 1 | BO32: 0 | BP32: 1 | BQ32: E-wallet | BR32: No | BS32: 0 | BT32: 0 | BU32: 0 | BV32: 0.04 | BW32: 0 | BX32: 0 | BY32: 0 | BZ32: No | CA32: Improved | CC32: 0 | CD32: 0 | CE32: 0.52 | CF32: 0 | CG32: 1 | CH32: -42 | CI32: -6.1 | CJ32: 0 | CK32: 6 | CL32: 0.05 | CM32: 0
A33: P028 | B33: 54 | C33: Male | D33: Sweden | E33: 1253 | F33: Low | G33: Yes | H33: 10 | I33: 14 | J33: 47.2 | K33: 57 | L33: 11 | M33: 0.01 | N33: 0.21 | O33: 0.14 | P33: 47 | Q33: 4 | R33: 0.4 | S33: 14 | T33: 422 | U33: 1 | V33: 1 | W33: 0 | X33: 47.5 | Y33: 53 | Z33: 0 | AA33: 0 | AB33: 0.24 | AC33: 5 | AD33: 57 | AE33: 0 | AF33: 0.68 | AG33: 0 | AH33: 202 | AI33: 188 | AJ33: 0.93 | AK33: 5 | AL33: 0.53 | AM33: -8.2 | AN33: 2.9 | AO33: 0.69 | AP33: 215 | AQ33: 22 | AR33: 1.144 | AS33: -3 | AT33: 0.19 | AU33: 37 | AV33: 3309 | AW33: 0.143 | AX33: 1 | AY33: 0.55 | AZ33: 2.9 | BA33: 1 | BB33: 0.09 | BC33: No | BD33: Yes | BE33: 0 | BF33: 0 | BG33: 0 | BH33: 0 | BI33: 0 | BK33: 4.4 | BL33: 0 | BM33: No | BN33: 2 | BO33: 0 | BP33: 1 | BQ33: E-wallet | BR33: No | BS33: 0.28 | BT33: 0 | BU33: 0.16 | BV33: 0.26 | BW33: 0 | BX33: 0 | BY33: 0 | BZ33: No | CA33: None | CC33: 0.7 | CD33: 0.1 | CE33: 0.37 | CF33: 0 | CG33: 1 | CH33: 5 | CI33: -9.8 | CJ33: 92 | CK33: 6 | CL33: 0.25 | CM33: 0
A34: P029 | B34: 25 | C34: Female | D34: Spain | E34: 1079 | F34: Low | G34: No | H34: 9 | I34: 18 | J34: 44.1 | K34: 101 | L34: 13.2 | M34: 0.15 | N34: 0.32 | O34: 0.07 | P34: 93 | Q34: 5 | R34: 1.3 | S34: 29 | T34: 996 | U34: 1.61 | V34: 1 | W34: 1 | X34: 21.4 | Y34: 28 | Z34: 0 | AA34: 0.12 | AB34: 0.71 | AC34: 4 | AD34: 20 | AE34: 1 | AF34: 0.75 | AG34: 0 | AH34: 831 | AI34: 1939 | AJ34: 2.33 | AK34: 15 | AL34: 0.75 | AM34: -1.2 | AN34: 5.4 | AO34: 0.93 | AP34: 403 | AQ34: 45 | AR34: 0.208 | AS34: 34 | AT34: 0.38 | AU34: 71 | AV34: 4760 | AW34: 0.269 | AX34: 1 | AY34: 0.63 | AZ34: 3.2 | BA34: 3.4 | BB34: 0.08 | BC34: No | BD34: Yes | BE34: 1 | BF34: 0 | BG34: 0 | BH34: 0 | BI34: 0 | BK34: 2.6 | BL34: 1 | BM34: No | BN34: 2 | BO34: 0 | BP34: 2 | BQ34: Card | BR34: No | BS34: 0.43 | BT34: 0 | BU34: 0.21 | BV34: 0.13 | BW34: 2 | BX34: 0 | BY34: 0 | BZ34: No | CA34: None | CC34: 1 | CD34: 0.11 | CE34: 0.72 | CF34: 0 | CG34: 1 | CH34: 35 | CI34: 2.3 | CJ34: 1923 | CK34: 6 | CL34: 0.36 | CM34: 0
A35: P030 | B35: 49 | C35: Female | D35: Denmark | E35: 505 | F35: Medium | G35: No | H35: 9 | I35: 12 | J35: 33.6 | K35: 61 | L35: 6.7 | M35: 0.13 | N35: 0.38 | O35: 0.1 | P35: 50 | Q35: 3 | R35: 1 | S35: 12 | T35: 988 | U35: 1 | V35: 1 | W35: 1 | X35: 65.9 | Y35: 49 | Z35: 0 | AA35: 0.13 | AB35: 0.41 | AC35: 4 | AD35: 60 | AE35: 0 | AF35: 0.74 | AG35: 0 | AH35: 692 | AI35: 909 | AJ35: 1.31 | AK35: 7 | AL35: 0.7 | AM35: 9.9 | AN35: 3.8 | AO35: 0.95 | AP35: 356 | AQ35: 40 | AR35: 0.392 | AS35: 7 | AT35: 0.3 | AU35: 186 | AV35: 1671 | AW35: 0.119 | AX35: 3 | AY35: 0.2 | AZ35: 2.9 | BA35: 3.2 | BB35: 0.21 | BC35: No | BD35: No | BE35: 0 | BF35: 0 | BG35: 0 | BH35: 0 | BI35: 0 | BK35: 6.7 | BL35: 0 | BM35: No | BN35: 2 | BO35: 1 | BP35: 1 | BQ35: E-wallet | BR35: No | BS35: 0.2 | BT35: 0 | BU35: 0.27 | BV35: 0.22 | BW35: 4 | BX35: 0 | BY35: 0 | BZ35: No | CA35: None | CC35: 2.1 | CD35: 0.1 | CE35: 0.71 | CF35: 0 | CG35: 1 | CH35: -16 | CI35: -5.3 | CJ35: 1050 | CK35: 6 | CL35: 0.46 | CM35: 0
A36: P031 | B36: 43 | C36: Female | D36: UK | E36: 683 | F36: Medium | G36: No | H36: 8 | I36: 8 | J36: 48.1 | K36: 105 | L36: 6.4 | M36: 0 | N36: 0.24 | O36: 0.11 | P36: 105 | Q36: 1 | R36: 0.3 | S36: 1 | T36: 11 | U36: 0.12 | V36: 1 | W36: 0 | X36: 508 | Y36: -51 | Z36: 1 | AA36: 0 | AB36: 0.17 | AC36: 2 | AD36: 151 | AE36: 1 | AF36: 0.71 | AG36: 0 | AH36: 40 | AI36: 8 | AJ36: 0.2 | AK36: 1 | AL36: 0.49 | AM36: -5.5 | AN36: 0.5 | AO36: 0.56 | AP36: 5 | AQ36: 1 | AR36: 0.625 | AS36: -36 | AT36: 0 | AU36: 0 | AV36: 66 | AW36: 0.002 | AX36: 1 | AY36: 0.25 | AZ36: 3.4 | BA36: 1 | BB36: 0.07 | BC36: No | BD36: No | BE36: 0 | BF36: 0 | BG36: 0 | BH36: 0 | BI36: 0 | BK36: 6.7 | BL36: 0 | BM36: No | BN36: 1 | BO36: 0 | BP36: 0 | BQ36: Card | BR36: No | BS36: 0 | BT36: 0 | BU36: 0.05 | BV36: 0.08 | BW36: 0 | BX36: 0 | BY36: 0 | BZ36: No | CA36: None | CC36: 0.2 | CD36: 0 | CE36: 0.41 | CF36: 0 | CG36: 1 | CH36: -62 | CI36: -3.8 | CJ36: 5 | CK36: 6 | CL36: 0.05 | CM36: 0
A37: P032 | B37: 53 | C37: Male | D37: Ontario | E37: 1006 | F37: Medium | G37: No | H37: 3 | I37: 4 | J37: 45.2 | K37: 124 | L37: 3 | M37: 0.06 | N37: 0.33 | O37: 0.16 | P37: 90 | Q37: 2 | R37: 0.1 | S37: 5 | T37: 50 | U37: 1.25 | V37: 1 | W37: 1 | X37: 185.2 | Y37: -7 | Z37: 0 | AA37: 0 | AB37: 0.48 | AC37: 4 | AD37: 38 | AE37: 0 | AF37: 0.85 | AG37: 0 | AH37: 240 | AI37: 471 | AJ37: 1.96 | AK37: 9 | AL37: 0.68 | AM37: 2.8 | AN37: 3.8 | AO37: 0.71 | AP37: 16 | AQ37: 5 | AR37: 0.034 | AS37: -21 | AT37: 0 | AU37: 5 | AV37: 322 | AW37: 0.005 | AX37: 1 | AY37: 0.18 | AZ37: 2.6 | BA37: 1 | BB37: 0.49 | BC37: No | BD37: No | BE37: 0 | BF37: 0 | BG37: 0 | BH37: 0 | BI37: 0 | BK37: 7.7 | BL37: 0 | BM37: No | BN37: 1 | BO37: 0 | BP37: 1 | BQ37: E-wallet | BR37: No | BS37: 0.31 | BT37: 0 | BU37: 0.2 | BV37: 0.18 | BW37: 1 | BX37: 0 | BY37: 0 | BZ37: No | CA37: None | CB37: 5 | CC37: 2.4 | CD37: 0.01 | CE37: 0.19 | CF37: 0 | CG37: 2 | CH37: 77 | CI37: 0.4 | CJ37: 349 | CK37: 6 | CL37: 0.27 | CM37: 0
A38: P033 | B38: 49 | C38: Male | D38: UK | E38: 628 | F38: High | G38: No | H38: 4 | I38: 4 | J38: 39 | K38: 96 | L38: 2.6 | M38: 0.04 | N38: 0.29 | O38: 0.06 | P38: 79 | Q38: 1 | R38: 0.4 | S38: 3 | T38: 33 | U38: 0.75 | V38: 1 | W38: 0 | X38: 253.1 | Y38: -11 | Z38: 0 | AA38: 0.07 | AB38: 0.26 | AC38: 2 | AD38: 116 | AE38: 0 | AF38: 0.87 | AG38: 0 | AH38: 64 | AI38: 113 | AJ38: 1.77 | AK38: 16 | AL38: 0.35 | AM38: -0.3 | AN38: 3.5 | AO38: 0.82 | AP38: 7 | AQ38: 2 | AR38: 0.062 | AS38: 21 | AT38: 0.03 | AU38: 3 | AV38: 68 | AW38: 0.001 | AX38: 1 | AY38: 0.5 | AZ38: 2.6 | BA38: 1 | BB38: 0 | BC38: No | BD38: Yes | BE38: 0 | BF38: 0 | BG38: 1 | BH38: 0 | BI38: 0 | BK38: 6.6 | BL38: 0 | BM38: No | BN38: 1 | BO38: 0 | BP38: 1 | BQ38: E-wallet | BR38: No | BS38: 0.23 | BT38: 0 | BU38: 0 | BV38: 0.23 | BW38: 0 | BX38: 0 | BY38: 0 | BZ38: No | CA38: None | CC38: 0.3 | CD38: 0 | CE38: 0.67 | CF38: 0 | CG38: 1 | CH38: -20 | CI38: -1.9 | CJ38: 82 | CK38: 6 | CL38: 0.05 | CM38: 0
A39: P034 | B39: 31 | C39: Female | D39: Denmark | E39: 317 | F39: High | G39: No | H39: 3 | I39: 4 | J39: 51.4 | K39: 79 | L39: 3.4 | M39: 0.09 | N39: 0.58 | O39: 0.15 | P39: 48 | Q39: 3 | R39: 0.6 | S39: 1 | T39: 22 | U39: 0.25 | V39: 1 | W39: 0 | X39: 684.3 | Y39: -47 | Z39: 1 | AA39: 0.09 | AB39: 0.72 | AC39: 3 | AD39: 123 | AE39: 0 | AF39: 0.91 | AG39: 0 | AH39: 83 | AI39: 101 | AJ39: 1.22 | AK39: 13 | AL39: 0.34 | AM39: -2.9 | AN39: 4.9 | AO39: 0.83 | AP39: 3 | AQ39: 1 | AR39: 0.03 | AS39: 11 | AT39: 0 | AU39: 1 | AV39: 16 | AW39: 0 | AX39: 1 | AY39: 0.32 | AZ39: 1.3 | BA39: 1 | BB39: 0.27 | BC39: No | BD39: No | BE39: 0 | BF39: 0 | BG39: 0 | BH39: 0 | BI39: 0 | BK39: 8.5 | BL39: 0 | BM39: No | BN39: 1 | BO39: 0 | BP39: 0 | BQ39: Card | BR39: No | BS39: 0.34 | BT39: 0 | BU39: 0.2 | BV39: 0.18 | BW39: 0 | BX39: 0 | BY39: 0 | BZ39: No | CA39: None | CC39: 1.3 | CD39: 0.13 | CE39: 0.67 | CF39: 0 | CG39: 1 | CH39: -21 | CI39: 0.4 | CJ39: 84 | CK39: 6 | CL39: 0.32 | CM39: 0
A40: P035 | B40: 48 | C40: Male | D40: UK | E40: 69 | F40: High | G40: No | H40: 18 | I40: 44 | J40: 4 | K40: 12 | L40: 2.9 | M40: 0.16 | N40: 0.23 | O40: 0.24 | P40: 9 | Q40: 6 | R40: 1.5 | S40: 65 | T40: 6436 | U40: 1.48 | V40: 3 | W40: 3 | X40: 9.5 | Y40: 12 | Z40: 1 | AA40: 0.18 | AB40: 0.66 | AC40: 3 | AD40: 109 | AE40: 1 | AF40: 0.46 | AG40: 1 | AH40: 2536 | AI40: 2771 | AJ40: 1.09 | AK40: 9 | AL40: 1 | AM40: 7.3 | AN40: 7.3 | AO40: 1.32 | AP40: 3853 | AQ40: 214 | AR40: 1.39 | AS40: 29 | AT40: 0.38 | AU40: 1245 | AV40: 6659 | AW40: 0.642 | AX40: 1 | AY40: 0.65 | AZ40: 3 | BA40: 3.5 | BB40: 0.37 | BC40: No | BD40: Yes | BE40: 1 | BF40: 1 | BG40: 0 | BH40: 1 | BI40: 1 | BJ40: 133 | BK40: 3.7 | BL40: 1 | BM40: No | BN40: 2 | BO40: 0 | BP40: 2 | BQ40: E-wallet | BR40: No | BS40: 0.43 | BT40: 1 | BU40: 0.48 | BV40: 0.37 | BW40: 3 | BX40: 1 | BY40: 0 | BZ40: No | CA40: Improved | CB40: 10 | CC40: 2.4 | CD40: 0.2 | CE40: 0.76 | CF40: 1 | CG40: 2 | CH40: 46 | CI40: 7.9 | CJ40: 4344 | CK40: 2 | CL40: 0.72 | CM40: 0
A41: P036 | B41: 61 | C41: Female | D41: Spain | E41: 829 | F41: High | G41: No | H41: 1 | I41: 1 | J41: 46.6 | K41: 115 | L41: 0.8 | M41: 0.04 | N41: 0.44 | O41: 0 | P41: 107 | Q41: 1 | R41: 0.1 | S41: 1 | T41: 32 | U41: 1 | V41: 1 | W41: 1 | X41: 606.6 | Y41: -11 | Z41: 1 | AA41: 0 | AB41: 0 | AC41: 3 | AD41: 35 | AE41: 0 | AF41: 0.57 | AG41: 0 | AH41: 13 | AI41: 9 | AJ41: 0.69 | AK41: 5 | AL41: 0.48 | AM41: -2.2 | AN41: 3.5 | AO41: 0.72 | AP41: 15 | AQ41: 15 | AR41: 1.667 | AS41: -50 | AT41: 0 | AU41: 5 | AV41: 278 | AW41: 0.002 | AX41: 1 | AY41: 0.35 | AZ41: 2 | BA41: 1.8 | BB41: 0.01 | BC41: No | BD41: No | BE41: 0 | BF41: 1 | BG41: 0 | BH41: 1 | BI41: 0 | BK41: 4.2 | BL41: 1 | BM41: No | BN41: 1 | BO41: 0 | BP41: 0 | BQ41: E-wallet | BR41: No | BS41: 0.1 | BT41: 0 | BU41: 0.14 | BV41: 0 | BW41: 1 | BX41: 0 | BY41: 0 | BZ41: No | CA41: None | CC41: 0.4 | CD41: 0.02 | CE41: 0.28 | CF41: 0 | CG41: 2 | CH41: 10 | CI41: -5.4 | CJ41: 8 | CK41: 6 | CL41: 0.28 | CM41: 0
...

Sheet Model Settings
A1: Model settings – indicators, thresholds and weights
A2: Blue cells are editable. Default thresholds ≈ top 20% of this synthetic data (or research rules where noted) – replace with your policy values.
A4: Model | B4: RG ID | C4: Data point | D4: Rule | E4: Threshold | F4: Weight | G4: Basis
A5: M1 Overall harm risk | B5: RG-020 | C5: Deposits per session | D5: >= | E5: 1.5 | F5: 3 | G5: Hopfgartner 2024 – strong predictor; ≈ top 20% of synthetic data
A6: M1 Overall harm risk | B6: RG-045 | C6: Account depletion | D6: >= | E6: 0.31 | F6: 3 | G6: Hopfgartner 2024 – strong predictor; ≈ top 20% of synthetic data
A7: M1 Overall harm risk | B7: RG-060 | C7: Self-exclusions | D7: >= | E7: 1 | F7: 3 | G7: Hopfgartner 2024; Perrot 2022
A8: M1 Overall harm risk | B8: RG-037 | C8: Stake variability | D8: >= | E8: 0.78 | F8: 2 | G8: Finkenwirth 2021 – top predictor; ≈ top 20% of synthetic data
A9: M1 Overall harm risk | B9: RG-033 | C9: Number of bets | D9: >= | E9: 903.2 | F9: 2 | G9: Finkenwirth 2021; ≈ top 20% of synthetic data
A10: M1 Overall harm risk | B10: RG-001 | C10: Age | D10: <= | E10: 25 | F10: 1 | G10: Hopfgartner 2024; DGOJ under-26 group
A11: M1 Overall harm risk | B11: RG-012 | C11: Night-time play | D11: >= | E11: 0.19 | F11: 2 | G11: DGOJ algorithm; ≈ top 20% of synthetic data
A12: M1 Overall harm risk | B12: RG-009 | C12: Average session length | D12: <= | E12: 25.84 | F12: 1 | G12: Hopfgartner 2024 (shorter sessions); ≈ bottom 20% of synthetic data
A13: M1 Overall harm risk | B13: RG-021 | C13: Multiple deposits in short time | D13: >= | E13: 3 | F13: 2 | G13: Perrot 2022 / Luquiens 2016: 3+ deposits in 12h
A14: M1 Overall harm risk | B14: RG-022 | C14: Deposit soon after a loss | D14: >= | E14: 2 | F14: 2 | G14: Perrot 2022: deposit within 1h of a bet
A15: M1 Overall harm risk | B15: RG-030 | C15: Cancelled / reversed withdrawals | D15: >= | E15: 1 | F15: 2 | G15: Catania & Griffiths 2021
A16: M1 Overall harm risk | B16: RG-057 | C16: Limit removals | D16: >= | E16: 1 | F16: 2 | G16: Catania & Griffiths 2021
... A35: M4 Financial vulnerability | B35: RG-067 | C35: Registered cards | D35: >= | E35: 3 | F35: 1 | G35: Catania 2021
A36: M4 Financial vulnerability | B36: RG-069 | C36: Third-party payment method | D36: = | E36: Yes | F36: 1 | G36: Possible borrowing
A37: M4 Financial vulnerability | B37: RG-048 | C37: Loss vs affordability | D37: >= | E37: 0.2 | F37: 1 | G37: Loss ≥ 20% of monthly income (policy example)
A38: M4 Financial vulnerability | B38: RG-031 | C38: Withdrawal-to-deposit ratio | D38: <= | E38: 0.2 | F38: 1 | G38: Rarely cashes out
A39: M5 Binge / episode | B39: RG-010 | C39: Maximum session length | D39: >= | E39: 101 | F39: 1 | G39: ≈ top 20% of synthetic data
A40: M5 Binge / episode | B40: RG-015 | C40: Continuous play without breaks | D40: >= | E40: 83 | F40: 1 | G40: DGOJ continuous play; ≈ top 20% of synthetic data
A41: M5 Binge / episode | B41: RG-012 | C41: Night-time play | D41: >= | E41: 0.19 | F41: 1 | G41: ≈ top 20% of synthetic data
A42: M5 Binge / episode | B42: RG-046 | C42: Large single-day loss | D42: >= | E42: 274.4 | F42: 1 | G42: Auer & Griffiths 2024; ≈ top 20% of synthetic data
A43: M5 Binge / episode | B43: RG-089 | C43: Behaviour volatility | D43: >= | E43: 0.53 | F43: 1 | G43: ≈ top 20% of synthetic data
A44: M5 Binge / episode | B44: RG-016 | C44: Consecutive days played | D44: >= | E44: 5 | F44: 1 | G44: ≈ top 20% of synthetic data
A45: M6 Self-exclusion prediction | B45: RG-056 | C45: Limit increases | D45: >= | E45: 1 | F45: 1 | G45: Hopfgartner 2023 – limit changes
A46: M6 Self-exclusion prediction | B46: RG-059 | C46: Time-outs / cool-offs | D46: >= | E46: 1 | F46: 1 | G46: Industry practice
A47: M6 Self-exclusion prediction | B47: RG-020 | C47: Deposits per session | D47: >= | E47: 1.5 | F47: 1 | G47: Hopfgartner 2023; ≈ top 20% of synthetic data
A48: M6 Self-exclusion prediction | B48: RG-065 | C48: Number of payment methods | D48: >= | E48: 3 | F48: 1 | G48: Hopfgartner 2023
... A63: M11 Spain DGOJ-style check | B63: RG-015 | C63: Continuous play without breaks | D63: >= | E63: 83 | F63: 1 | G63: Continuous play; ≈ top 20% of synthetic data
A65: Overall risk bands (M1 score, 0–100)
A66: Medium if M1 ≥ | E66: 20
A67: High if M1 ≥ | E67: 40
A68: Score ≥ this % counts as a flag (M2–M6, M10, M11) | E68: 50
A69: Early-warning applies if account age ≤ (days) | E69: 90
A70: Count as 'flagged' for accuracy test (High or High+Medium) | E70: High

Sheet Model Results
A1: Model results – 12 RG models per player
A2: All cells are formulas reading Player Data and Model Settings. Scores 0–100 (% of weighted warning signs triggered). Rule-based versions of the models; ML versions are built in Python.
A5: Player ID | B5: M1 Overall harm risk (0–100) | C5: M2 Early warning | D5: M3 Chasing losses | E5: M4 Financial vulnerability | F5: M5 Binge / episode | G5: M6 Self-exclusion prediction | H5: M7 Player segment | I5: M8 Harm language alert | J5: M9 Marketing filter | K5: M10 Behaviour change | L5: M11 Spain DGOJ-style check | M5: M12 Intervention effectiveness | N5: Overall risk band | O5: Recommended action | P5: Flagged (1/0) | Q5: Simulated outcome (test only)
A6: ='Player Data'!A6 -> P001 | B6: =ROUND(100*((N('Player Data'!U6)>='Model Settings'!$E$5)*'Model Settings'!$F$5+(N('Player Data'!AT6)>='Model Settings'!$E$6)*'Model Settings'!$F$6+(N('Player Data'!BI6)>='Model Settings'!$E$7)*'Model Settings'!$F$7+(N('Player Data'!AL6)>='Model Settings'!$E$8)*'Model Settings'!$F$8+(N('Player Data'!AH6)>='Model Settings'!$E$9)*'Model Settings'!$F$9+(N('Player Data'!B6)<='Model Settings'!$E$10)*'Model Settings'!$F$10+(N('Player Data'!M6)>='Model Settings'!$E$11)*'Model Settings'!$F$11+(N('Player Data'!J6)<='Model Settings'!$E$12)*'Model Settings'!$F$12+(N('Player Data'!V6)>='Model Settings'!$E$13)*'Model Settings'!$F$13+(N('Player Data'!W6)>='Model Settings'!$E$14)*'Model Settings'!$F$14+(N('Player Data'!AE6)>='Model Settings'!$E$15)*'Model Settings'!$F$15+(N('Player Data'!BF6)>='Model Settings'!$E$16)*'Model Settings'!$F$16+(N('Player Data'!AX6)>='Model Settings'!$E$17)*'Model Settings'!$F$17+(N('Player Data'!AP6)>='Model Settings'!$E$18)*'Model Settings'!$F$18)/('Model Settings'!$F$5+'Model Settings'!$F$6+'Model Settings'!$F$7+'Model Settings'!$F$8+'Model Settings'!$F$9+'Model Settings'!$F$10+'Model Settings'!$F$11+'Model Settings'!$F$12+'Model Settings'!$F$13+'Model Settings'!$F$14+'Model Settings'!$F$15+'Model Settings'!$F$16+'Model Settings'!$F$17+'Model Settings'!$F$18),0) -> 7 | C6: =IF('Player Data'!E6<='Model Settings'!$E$69,ROUND(100*((N('Player Data'!H6)>='Model Settings'!$E$19)*'Model Settings'!$F$19+(N('Player Data'!S6)>='Model Settings'!$E$20)*'Model Settings'!$F$20+(N('Player Data'!AH6)>='Model Settings'!$E$21)*'Model Settings'!$F$21+(N('Player Data'!AX6)>='Model Settings'!$E$22)*'Model Settings'!$F$22+(N('Player Data'!Y6)>='Model Settings'!$E$23)*'Model Settings'!$F$23+(N('Player Data'!AM6)>='Model Settings'!$E$24)*'Model Settings'!$F$24)/('Model Settings'!$F$19+'Model Settings'!$F$20+'Model Settings'!$F$21+'Model Settings'!$F$22+'Model Settings'!$F$23+'Model Settings'!$F$24),0),"n/a") -> n/a | D6: =ROUND(100*((N('Player Data'!U6)>='Model Settings'!$E$25)*'Model Settings'!$F$25+(N('Player Data'!V6)>='Model Settings'!$E$26)*'Model Settings'!$F$26+(N('Player Data'!W6)>='Model Settings'!$E$27)*'Model Settings'!$F$27+(N('Player Data'!AT6)>='Model Settings'!$E$28)*'Model Settings'!$F$28+(N('Player Data'!AE6)>='Model Settings'!$E$29)*'Model Settings'!$F$29+(N('Player Data'!AO6)>='Model Settings'!$E$30)*'Model Settings'!$F$30+(N('Player Data'!AG6)>='Model Settings'!$E$31)*'Model Settings'!$F$31)/('Model Settings'!$F$25+'Model Settings'!$F$26+'Model Settings'!$F$27+'Model Settings'!$F$28+'Model Settings'!$F$29+'Model Settings'!$F$30+'Model Settings'!$F$31),0) -> 0 | E6: =ROUND(100*((N('Player Data'!Z6)>='Model Settings'!$E$32)*'Model Settings'!$F$32+(N('Player Data'!BN6)>='Model Settings'!$E$33)*'Model Settings'!$F$33+(N('Player Data'!BO6)>='Model Settings'!$E$34)*'Model Settings'!$F$34+(N('Player Data'!BP6)>='Model Settings'!$E$35)*'Model Settings'!$F$35+('Player Data'!BR6='Model Settings'!$E$36)*'Model Settings'!$F$36+(N('Player Data'!AW6)>='Model Settings'!$E$37)*'Model Settings'!$F$37+(N('Player Data'!AF6)<='Model Settings'!$E$38)*'Model Settings'!$F$38)/('Model Settings'!$F$32+'Model Settings'!$F$33+'Model Settings'!$F$34+'Model Settings'!$F$35+'Model Settings'!$F$36+'Model Settings'!$F$37+'Model Settings'!$F$38),0) -> 14 | F6: =ROUND(100*((N('Player Data'!K6)>='Model Settings'!$E$39)*'Model Settings'!$F$39+(N('Player Data'!P6)>='Model Settings'!$E$40)*'Model Settings'!$F$40+(N('Player Data'!M6)>='Model Settings'!$E$41)*'Model Settings'!$F$41+(N('Player Data'!AU6)>='Model Settings'!$E$42)*'Model Settings'!$F$42+(N('Player Data'!CL6)>='Model Settings'!$E$43)*'Model Settings'!$F$43+(N('Player Data'!Q6)>='Model Settings'!$E$44)*'Model Settings'!$F$44)/('Model Settings'!$F$39+'Model Settings'!$F$40+'Model Settings'!$F$41+'Model Settings'!$F$42+'Model Settings'!$F$43+'Model Settings'!$F$44),0) -> 50 | G6: =ROUND(100*((N('Player Data'!BE6)>='Model Settings'!$E$45)*'Model Settings'!$F$45+(N('Player Data'!BH6)>='Model Settings'!$E$46)*'Model Settings'!$F$46+(N('Player Data'!U6)>='Model Settings'!$E$47)*'Model Settings'!$F$47+(N('Player Data'!BN6)>='Model Settings'!$E$48)*'Model Settings'!$F$48+(N('Player Data'!AX6)>='Model Settings'!$E$49)*'Model Settings'!$F$49+(N('Player Data'!BL6)>='Model Settings'!$E$50)*'Model Settings'!$F$50+(N('Player Data'!BI6)>='Model Settings'!$E$51)*'Model Settings'!$F$51)/('Model Settings'!$F$45+'Model Settings'!$F$46+'Model Settings'!$F$47+'Model Settings'!$F$48+'Model Settings'!$F$49+'Model Settings'!$F$50+'Model Settings'!$F$51),0) -> 43 | H6: =IF(AND(B6<'Model Settings'!$E$66,E6<'Model Settings'!$E$68),"Non-problem",IF(E6>='Model Settings'!$E$68,"Financially vulnerable",IF(OR(N('Player Data'!BY6)>=1,N('Player Data'!BX6)>=2,N('Player Data'!BW6)>=3),"Emotionally vulnerable","At-risk"))) -> Non-problem | I6: =IF(OR(N('Player Data'!BY6)>=1,'Player Data'!BZ6="Yes"),"Alert","None") -> None | J6: =IF(OR(B6>='Model Settings'!$E$67,'Player Data'!BM6="Yes",I6="Alert"),"Suppress",IF(AND(B6>='Model Settings'!$E$66,'Player Data'!G6="Yes"),"Review VIP","Allow")) -> Allow | K6: =ROUND(100*((N('Player Data'!CH6)>='Model Settings'!$E$52)*'Model Settings'!$F$52+(N('Player Data'!CI6)>='Model Settings'!$E$53)*'Model Settings'!$F$53+(N('Player Data'!R6)>='Model Settings'!$E$54)*'Model Settings'!$F$54+(N('Player Data'!Y6)>='Model Settings'!$E$55)*'Model Settings'!$F$55+(N('Player Data'!AS6)>='Model Settings'!$E$56)*'Model Settings'!$F$56)/('Model Settings'!$F$52+'Model Settings'!$F$53+'Model Settings'!$F$54+'Model Settings'!$F$55+'Model Settings'!$F$56),0) -> 60 | L6: =IF('Player Data'!D6="Spain",ROUND(100*((N('Player Data'!H6)>='Model Settings'!$E$57)*'Model Settings'!$F$57+(N('Player Data'!AI6)>='Model Settings'!$E$58)*'Model Settings'!$F$58+(N('Player Data'!AL6)>='Model Settings'!$E$59)*'Model Settings'!$F$59+(N('Player Data'!M6)>='Model Settings'!$E$60)*'Model Settings'!$F$60+(N('Player Data'!X6)<='Model Settings'!$E$61)*'Model Settings'!$F$61+(N('Player Data'!Y6)>='Model Settings'!$E$62)*'Model Settings'!$F$62+(N('Player Data'!P6)>='Model Settings'!$E$63)*'Model Settings'!$F$63)/('Model Settings'!$F$57+'Model Settings'!$F$58+'Model Settings'!$F$59+'Model Settings'!$F$60+'Model Settings'!$F$61+'Model Settings'!$F$62+'Model Settings'!$F$63),0),"n/a") -> n/a | M6: =IF('Player Data'!CA6="None","No contact yet",IF('Player Data'!CA6="Improved","Working",IF('Player Data'!CA6="No change","Review approach","Escalate"))) -> No contact yet | N6: =IF(OR('Player Data'!BM6="Yes",I6="Alert"),"High",IF(B6>='Model Settings'!$E$67,"High",IF(OR(B6>='Model Settings'!$E$66,D6>='Model Settings'!$E$68,F6>='Model Settings'!$E$68,K6>='Model Settings'!$E$68),"Medium","Low"))) -> Medium | O6: =IF(N6="High","Contact player + review within 48h; stop marketing",IF(N6="Medium","Safer gambling message; monitor weekly","No action; routine monitoring")) -> Safer gambling message; monitor weekly | P6: =IF(OR(N6="High",AND('Model Settings'!$E$70="High+Medium",N6="Medium")),1,0) -> 0 | Q6: ='Player Data'!CM6 -> 0
